Traceback (most recent call last):
  File "C:\python_venv\psqlpy_venv\Lib\site-packages\jupyter_cache\executors\utils.py", line 58, in single_nb_execution
    executenb(
  File "C:\python_venv\psqlpy_venv\Lib\site-packages\nbclient\client.py", line 1305, in execute
    return NotebookClient(nb=nb, resources=resources, km=km, **kwargs).execute()
           ^^^^^^^^^^^^^^^^^^^^^^^^^^^^^^^^^^^^^^^^^^^^^^^^^^^^^^^^^^^^^^^^^^^^^
  File "C:\python_venv\psqlpy_venv\Lib\site-packages\jupyter_core\utils\__init__.py", line 173, in wrapped
    return loop.run_until_complete(inner)
           ^^^^^^^^^^^^^^^^^^^^^^^^^^^^^^
  File "C:\Program Files\WindowsApps\PythonSoftwareFoundation.Python.3.11_3.11.1776.0_x64__qbz5n2kfra8p0\Lib\asyncio\base_events.py", line 653, in run_until_complete
    return future.result()
           ^^^^^^^^^^^^^^^
  File "C:\python_venv\psqlpy_venv\Lib\site-packages\nbclient\client.py", line 705, in async_execute
    await self.async_execute_cell(
  File "C:\python_venv\psqlpy_venv\Lib\site-packages\nbclient\client.py", line 1058, in async_execute_cell
    await self._check_raise_for_error(cell, cell_index, exec_reply)
  File "C:\python_venv\psqlpy_venv\Lib\site-packages\nbclient\client.py", line 914, in _check_raise_for_error
    raise CellExecutionError.from_cell_and_msg(cell, exec_reply_content)
nbclient.exceptions.CellExecutionError: An error occurred while executing the following cell:
------------------
import pandas as pd
from time import mktime
from datetime import datetime, timedelta
import time
import seaborn as sns
import matplotlib.pyplot as plt
from statsmodels.tsa.stattools import adfuller
from numpy import log
from statsmodels.graphics.tsaplots import plot_acf
from statsmodels.graphics.tsaplots import plot_predict
from sklearn.metrics import r2_score
import numpy as np
from sklearn.metrics import mean_absolute_error
from sklearn.metrics import mean_squared_error
from sklearn.metrics import mean_squared_log_error
from sklearn.metrics import r2_score
from sklearn.preprocessing import StandardScaler
import itertools
from scipy import stats
from statsmodels.tsa.arima.model import ARIMA
import statsmodels.api as sm
from sklearn.linear_model import Ridge
import warnings
warnings.filterwarnings("ignore", category=UserWarning, module="seaborn")
from sklearn.model_selection import ParameterGrid
tf.get_logger().setLevel(tf.compat.v1.logging.ERROR)
warnings.filterwarnings("ignore", category=DeprecationWarning)
warnings.filterwarnings("ignore", category=FutureWarning)
------------------


[1;31m---------------------------------------------------------------------------[0m
[1;31mNameError[0m                                 Traceback (most recent call last)
Cell [1;32mIn[1], line 26[0m
[0;32m     24[0m warnings[38;5;241m.[39mfilterwarnings([38;5;124m"[39m[38;5;124mignore[39m[38;5;124m"[39m, category[38;5;241m=[39m[38;5;167;01mUserWarning[39;00m, module[38;5;241m=[39m[38;5;124m"[39m[38;5;124mseaborn[39m[38;5;124m"[39m)
[0;32m     25[0m [38;5;28;01mfrom[39;00m [38;5;21;01msklearn[39;00m[38;5;21;01m.[39;00m[38;5;21;01mmodel_selection[39;00m [38;5;28;01mimport[39;00m ParameterGrid
[1;32m---> 26[0m [43mtf[49m[38;5;241m.[39mget_logger()[38;5;241m.[39msetLevel(tf[38;5;241m.[39mcompat[38;5;241m.[39mv1[38;5;241m.[39mlogging[38;5;241m.[39mERROR)
[0;32m     27[0m warnings[38;5;241m.[39mfilterwarnings([38;5;124m"[39m[38;5;124mignore[39m[38;5;124m"[39m, category[38;5;241m=[39m[38;5;167;01mDeprecationWarning[39;00m)
[0;32m     28[0m warnings[38;5;241m.[39mfilterwarnings([38;5;124m"[39m[38;5;124mignore[39m[38;5;124m"[39m, category[38;5;241m=[39m[38;5;167;01mFutureWarning[39;00m)

[1;31mNameError[0m: name 'tf' is not defined

